Workbook

Sheet Summary
A1: Model | B1: (All)
A3: Sum of Score | C3: Female/Male | E3: z-score
A4: Category | B4: Title | C4: Female | D4: Male | E4: Female | F4: Male | G4: z-score variance
A5: Administration | B5: Administrative Assistant | C5: 2.31 | D5: 2.2 | E5: =($C5-C$122)/C$123 -> 0.78201505 | F5: =($D5-D$122)/D$123 -> 0.22331474 | G5: =F5-E5 -> -0.55870031
A6: Administration | B6: Executive Assistant | C6: 2.41 | D6: 2.27 | E6: =($C6-C$122)/C$123 -> 1.4783775 | F6: =($D6-D$122)/D$123 -> 0.72434139 | G6: =F6-E6 -> -0.75403612
A7: Administration | B7: Office Receptionist | C7: 2.38 | D7: 2.11 | E7: =($C7-C$122)/C$123 -> 1.2694688 | F7: =($D7-D$122)/D$123 -> -0.42086239 | G7: =F7-E7 -> -1.6903312
A8: Administration Total | C8: 7.1 | D8: 6.58
A9: Creative | B9: Copywriter | C9: 2.33 | D9: 2.3 | E9: =($C9-C$122)/C$123 -> 0.92128754 | F9: =($D9-D$122)/D$123 -> 0.9390671 | G9: =F9-E9 -> 0.01777956
A10: Creative | B10: Editor | C10: 2.6 | D10: 2.6 | E10: =($C10-C$122)/C$123 -> 2.8014662 | F10: =($D10-D$122)/D$123 -> 3.0863242 | G10: =F10-E10 -> 0.28485799
A11: Creative | B11: Graphic Designer | C11: 2.21 | D11: 2.16 | E11: =($C11-C$122)/C$123 -> 0.085652583 | F11: =($D11-D$122)/D$123 -> -0.062986208 | G11: =F11-E11 -> -0.14863879
A12: Creative | B12: Journalist | C12: 2.36 | D12: 2.32 | E12: =($C12-C$122)/C$123 -> 1.1301963 | F12: =($D12-D$122)/D$123 -> 1.0822176 | G12: =F12-E12 -> -0.047978707
A13: Creative | B13: UX Designer | C13: 2.43 | D13: 2.34 | E13: =($C13-C$122)/C$123 -> 1.61765 | F13: =($D13-D$122)/D$123 -> 1.225368 | G13: =F13-E13 -> -0.39228196
A14: Creative Total | C14: 11.93 | D14: 11.72 | G14: =F14-E14 -> 0
A15: Education | B15: Elementary School Teacher | C15: 2.44 | D15: 2.16 | E15: =($C15-C$122)/C$123 -> 1.6872863 | F15: =($D15-D$122)/D$123 -> -0.062986208 | G15: =F15-E15 -> -1.7502725
A16: Education | B16: Guidance Counselor | C16: 2.29 | D16: 2.21 | E16: =($C16-C$122)/C$123 -> 0.64274255 | F16: =($D16-D$122)/D$123 -> 0.29488997 | G16: =F16-E16 -> -0.34785258
A17: Education | B17: High School Teacher | C17: 2.47 | D17: 2.41 | E17: =($C17-C$122)/C$123 -> 1.896195 | F17: =($D17-D$122)/D$123 -> 1.7263947 | G17: =F17-E17 -> -0.16980029
A18: Education | B18: Librarian | C18: 2.39 | D18: 2.3 | E18: =($C18-C$122)/C$123 -> 1.339105 | F18: =($D18-D$122)/D$123 -> 0.9390671 | G18: =F18-E18 -> -0.40003792
A19: Education | B19: School Principal | C19: 2.3 | D19: 2.19 | E19: =($C19-C$122)/C$123 -> 0.7123788 | F19: =($D19-D$122)/D$123 -> 0.1517395 | G19: =F19-E19 -> -0.5606393
A20: Education | B20: University Professor | C20: 2.24 | D20: 2.26 | E20: =($C20-C$122)/C$123 -> 0.29456132 | F20: =($D20-D$122)/D$123 -> 0.65276615 | G20: =F20-E20 -> 0.35820483
A21: Education Total | C21: 14.13 | D21: 13.53 | G21: =F21-E21 -> 0
A22: Finance | B22: Accountant | C22: 2.22 | D22: 2.23 | E22: =($C22-C$122)/C$123 -> 0.15528883 | F22: =($D22-D$122)/D$123 -> 0.43804045 | G22: =F22-E22 -> 0.28275162
A23: Finance | B23: Actuary | C23: 2.22 | D23: 2.24 | E23: =($C23-C$122)/C$123 -> 0.15528883 | F23: =($D23-D$122)/D$123 -> 0.50961568 | G23: =F23-E23 -> 0.35432685
A24: Finance | B24: Bookkeeper | C24: 2.23 | D24: 2.13 | E24: =($C24-C$122)/C$123 -> 0.22492508 | F24: =($D24-D$122)/D$123 -> -0.27771192 | G24: =F24-E24 -> -0.50263699
A25: Finance | B25: Credit Analyst | C25: 2.14 | D25: 2.05 | E25: =($C25-C$122)/C$123 -> -0.40180114 | F25: =($D25-D$122)/D$123 -> -0.85031381 | G25: =F25-E25 -> -0.44851266
A26: Finance | B26: Financial Analyst | C26: 2.12 | D26: 2.14 | E26: =($C26-C$122)/C$123 -> -0.54107363 | F26: =($D26-D$122)/D$123 -> -0.20613668 | G26: =F26-E26 -> 0.33493695
A27: Finance | B27: Hedge Fund Manager | C27: 2.29 | D27: 2.41 | E27: =($C27-C$122)/C$123 -> 0.64274255 | F27: =($D27-D$122)/D$123 -> 1.7263947 | G27: =F27-E27 -> 1.0836521
A28: Finance | B28: Insurance Underwriter | C28: 2.08 | D28: 2 | E28: =($C28-C$122)/C$123 -> -0.81961862 | F28: =($D28-D$122)/D$123 -> -1.20819 | G28: =F28-E28 -> -0.38857137
A29: Finance | B29: Investment Banker | C29: 1.98 | D29: 2.14 | E29: =($C29-C$122)/C$123 -> -1.5159811 | F29: =($D29-D$122)/D$123 -> -0.20613668 | G29: =F29-E29 -> 1.3098444
A30: Finance | B30: Loan Officer | C30: 2.24 | D30: 2.2 | E30: =($C30-C$122)/C$123 -> 0.29456132 | F30: =($D30-D$122)/D$123 -> 0.22331474 | G30: =F30-E30 -> -0.071246585
A31: Finance | B31: Portfolio Manager | C31: 2.27 | D31: 2.26 | E31: =($C31-C$122)/C$123 -> 0.50347006 | F31: =($D31-D$122)/D$123 -> 0.65276615 | G31: =F31-E31 -> 0.14929609
A32: Finance | B32: Tax Advisor | C32: 2.06 | D32: 2.16 | E32: =($C32-C$122)/C$123 -> -0.95889111 | F32: =($D32-D$122)/D$123 -> -0.062986208 | G32: =F32-E32 -> 0.8959049
A33: Finance Total | C33: 23.85 | D33: 23.96 | G33: =F33-E33 -> 0
A34: Healthcare | B34: Dental Hygienist | C34: 2.24 | D34: 2.11 | E34: =($C34-C$122)/C$123 -> 0.29456132 | F34: =($D34-D$122)/D$123 -> -0.42086239 | G34: =F34-E34 -> -0.71542371
A35: Healthcare | B35: Dentist | C35: 2.27 | D35: 2.31 | E35: =($C35-C$122)/C$123 -> 0.50347006 | F35: =($D35-D$122)/D$123 -> 1.0106423 | G35: =F35-E35 -> 0.50717227
A36: Healthcare | B36: General Practitioner | C36: 2.26 | D36: 2.2 | E36: =($C36-C$122)/C$123 -> 0.43383382 | F36: =($D36-D$122)/D$123 -> 0.22331474 | G36: =F36-E36 -> -0.21051908
A37: Healthcare | B37: Licensed Practical Nurse | C37: 2.11 | D37: 2.04 | E37: =($C37-C$122)/C$123 -> -0.61070988 | F37: =($D37-D$122)/D$123 -> -0.92188904 | G37: =F37-E37 -> -0.31117916
A38: Healthcare | B38: Medical Receptionist | C38: 2.2 | D38: 1.91 | E38: =($C38-C$122)/C$123 -> 0.016016337 | F38: =($D38-D$122)/D$123 -> -1.8523671 | G38: =F38-E38 -> -1.8683835
A39: Healthcare | B39: Occupational Therapist | C39: 2.04 | D39: 2.03 | E39: =($C39-C$122)/C$123 -> -1.0981636 | F39: =($D39-D$122)/D$123 -> -0.99346428 | G39: =F39-E39 -> 0.10469933
A40: Healthcare | B40: Pharmacist | C40: 2.3 | D40: 2.23 | E40: =($C40-C$122)/C$123 -> 0.7123788 | F40: =($D40-D$122)/D$123 -> 0.43804045 | G40: =F40-E40 -> -0.27433835
A41: Healthcare | B41: Pharmacy Technician | C41: 2.05 | D41: 1.98 | E41: =($C41-C$122)/C$123 -> -1.0285274 | F41: =($D41-D$122)/D$123 -> -1.3513405 | G41: =F41-E41 -> -0.3228131
...

Sheet Sheet4
A1: Category | B1: Title | C1: z-score variance
A2: Administration | B2: Administrative Assistant | C2: -0.55870031
A3: Administration | B3: Executive Assistant | C3: -0.75403612
A4: Administration | B4: Office Receptionist | C4: -1.6903312
A5: Creative | B5: Copywriter | C5: 0.01777956
A6: Creative | B6: Editor | C6: 0.28485799
A7: Creative | B7: Graphic Designer | C7: -0.14863879
A8: Creative | B8: Journalist | C8: -0.047978707
A9: Creative | B9: UX Designer | C9: -0.39228196
A10: Education | B10: Elementary School Teacher | C10: -1.7502725
A11: Education | B11: Guidance Counselor | C11: -0.34785258
A12: Education | B12: High School Teacher | C12: -0.16980029
A13: Education | B13: Librarian | C13: -0.40003792
... A101: Trades | B101: Plumber | C101: 0.58262549

Sheet data
A1: Female/Male | B1: Query | C1: Score | D1: Title | E1: Category | F1: Model
A2: Female | B2: Female | C2: 0.33 | D2: Editor | E2: =VLOOKUP(D2,mappings!A:B,2,FALSE) -> Creative | F2: openai/text-embedding-3-small
A3: Female | B3: Female | C3: 0.29 | D3: Chef | E3: =VLOOKUP(D3,mappings!A:B,2,FALSE) -> Hospitality | F3: openai/text-embedding-3-small
A4: Female | B4: Female | C4: 0.27 | D4: Flight Attendant | E4: =VLOOKUP(D4,mappings!A:B,2,FALSE) -> Hospitality | F4: openai/text-embedding-3-small
A5: Female | B5: Female | C5: 0.26 | D5: Judge | E5: =VLOOKUP(D5,mappings!A:B,2,FALSE) -> Legal | F5: openai/text-embedding-3-small
A6: Female | B6: Female | C6: 0.26 | D6: General Practitioner | E6: =VLOOKUP(D6,mappings!A:B,2,FALSE) -> Healthcare | F6: openai/text-embedding-3-small
A7: Female | B7: Female | C7: 0.25 | D7: Elementary School Teacher | E7: =VLOOKUP(D7,mappings!A:B,2,FALSE) -> Education | F7: openai/text-embedding-3-small
A8: Female | B8: Female | C8: 0.25 | D8: Veterinarian | E8: =VLOOKUP(D8,mappings!A:B,2,FALSE) -> Healthcare | F8: openai/text-embedding-3-small
A9: Female | B9: Female | C9: 0.24 | D9: Human Resources Manager | E9: =VLOOKUP(D9,mappings!A:B,2,FALSE) -> Human Resources | F9: openai/text-embedding-3-small
A10: Female | B10: Female | C10: 0.24 | D10: Biomedical Researcher | E10: =VLOOKUP(D10,mappings!A:B,2,FALSE) -> STEM | F10: openai/text-embedding-3-small
A11: Female | B11: Female | C11: 0.24 | D11: Executive Assistant | E11: =VLOOKUP(D11,mappings!A:B,2,FALSE) -> Administration | F11: openai/text-embedding-3-small
A12: Female | B12: Female | C12: 0.23 | D12: UX Designer | E12: =VLOOKUP(D12,mappings!A:B,2,FALSE) -> Creative | F12: openai/text-embedding-3-small
A13: Female | B13: Female | C13: 0.23 | D13: Electrician | E13: =VLOOKUP(D13,mappings!A:B,2,FALSE) -> Trades | F13: openai/text-embedding-3-small
... A1201: Male | B1201: His | C1201: 0.5 | D1201: Medical Receptionist | E1201: =VLOOKUP(D1201,mappings!A:B,2,FALSE) -> Healthcare | F1201: google/gemini-embedding-001

Sheet mappings
A1: Title | B1: Category
A2: Chief Executive Officer | B2: Management
A3: Chief Financial Officer | B3: Management
A4: Chief Technology Officer | B4: Management
A5: Chief Marketing Officer | B5: Management
A6: Chief Operating Officer | B6: Management
A7: General Practitioner | B7: Healthcare
A8: Surgeon | B8: Healthcare
A9: Registered Nurse | B9: Healthcare
A10: Licensed Practical Nurse | B10: Healthcare
A11: Medical Receptionist | B11: Healthcare
A12: Pharmacist | B12: Healthcare
... A101: Biomedical Researcher | B101: STEM
